2021-03-08 04:05:04,471 INFO: Microblog startup [in /home/tom/moringa-core/Flask/blog/app/__init__.py:43]
2021-03-08 04:13:32,764 INFO: Microblog startup [in /home/tom/moringa-core/Flask/blog/app/__init__.py:43]
2021-03-09 13:27:37,606 INFO: Microblog startup [in /home/tom/moringa-core/Flask/blog/app/__init__.py:68]
2021-03-09 13:27:40,526 ERROR: Exception on / [GET] [in /home/tom/moringa-core/Flask/blog/env/lib/python3.8/site-packages/flask/app.py:1891]
Traceback (most recent call last):
  File "/home/tom/moringa-core/Flask/blog/env/lib/python3.8/site-packages/flask/app.py", line 2447, in wsgi_app
    response = self.full_dispatch_request()
  File "/home/tom/moringa-core/Flask/blog/env/lib/python3.8/site-packages/flask/app.py", line 1952, in full_dispatch_request
    rv = self.handle_user_exception(e)
  File "/home/tom/moringa-core/Flask/blog/env/lib/python3.8/site-packages/flask/app.py", line 1821, in handle_user_exception
    reraise(exc_type, exc_value, tb)
  File "/home/tom/moringa-core/Flask/blog/env/lib/python3.8/site-packages/flask/_compat.py", line 39, in reraise
    raise value
  File "/home/tom/moringa-core/Flask/blog/env/lib/python3.8/site-packages/flask/app.py", line 1948, in full_dispatch_request
    rv = self.preprocess_request()
  File "/home/tom/moringa-core/Flask/blog/env/lib/python3.8/site-packages/flask/app.py", line 2242, in preprocess_request
    rv = func()
  File "/home/tom/moringa-core/Flask/blog/app/main/routes.py", line 16, in before_request
    g.locale = str(getocale())
NameError: name 'getocale' is not defined
2021-03-09 13:27:41,336 ERROR: Exception on /favicon.ico [GET] [in /home/tom/moringa-core/Flask/blog/env/lib/python3.8/site-packages/flask/app.py:1891]
Traceback (most recent call last):
  File "/home/tom/moringa-core/Flask/blog/env/lib/python3.8/site-packages/flask/app.py", line 2447, in wsgi_app
    response = self.full_dispatch_request()
  File "/home/tom/moringa-core/Flask/blog/env/lib/python3.8/site-packages/flask/app.py", line 1952, in full_dispatch_request
    rv = self.handle_user_exception(e)
  File "/home/tom/moringa-core/Flask/blog/env/lib/python3.8/site-packages/flask/app.py", line 1821, in handle_user_exception
    reraise(exc_type, exc_value, tb)
  File "/home/tom/moringa-core/Flask/blog/env/lib/python3.8/site-packages/flask/_compat.py", line 39, in reraise
    raise value
  File "/home/tom/moringa-core/Flask/blog/env/lib/python3.8/site-packages/flask/app.py", line 1948, in full_dispatch_request
    rv = self.preprocess_request()
  File "/home/tom/moringa-core/Flask/blog/env/lib/python3.8/site-packages/flask/app.py", line 2242, in preprocess_request
    rv = func()
  File "/home/tom/moringa-core/Flask/blog/app/main/routes.py", line 16, in before_request
    g.locale = str(getocale())
NameError: name 'getocale' is not defined
2021-03-09 13:38:15,525 INFO: Microblog startup [in /home/tom/moringa-core/Flask/blog/app/__init__.py:68]
2021-03-09 13:38:18,101 ERROR: Exception on / [GET] [in /home/tom/moringa-core/Flask/blog/env/lib/python3.8/site-packages/flask/app.py:1891]
Traceback (most recent call last):
  File "/home/tom/moringa-core/Flask/blog/env/lib/python3.8/site-packages/flask/app.py", line 2447, in wsgi_app
    response = self.full_dispatch_request()
  File "/home/tom/moringa-core/Flask/blog/env/lib/python3.8/site-packages/flask/app.py", line 1952, in full_dispatch_request
    rv = self.handle_user_exception(e)
  File "/home/tom/moringa-core/Flask/blog/env/lib/python3.8/site-packages/flask/app.py", line 1821, in handle_user_exception
    reraise(exc_type, exc_value, tb)
  File "/home/tom/moringa-core/Flask/blog/env/lib/python3.8/site-packages/flask/_compat.py", line 39, in reraise
    raise value
  File "/home/tom/moringa-core/Flask/blog/env/lib/python3.8/site-packages/flask/app.py", line 1948, in full_dispatch_request
    rv = self.preprocess_request()
  File "/home/tom/moringa-core/Flask/blog/env/lib/python3.8/site-packages/flask/app.py", line 2242, in preprocess_request
    rv = func()
  File "/home/tom/moringa-core/Flask/blog/app/main/routes.py", line 16, in before_request
    g.locale = str(getocale())
NameError: name 'getocale' is not defined
2021-03-09 13:38:18,500 ERROR: Exception on /favicon.ico [GET] [in /home/tom/moringa-core/Flask/blog/env/lib/python3.8/site-packages/flask/app.py:1891]
Traceback (most recent call last):
  File "/home/tom/moringa-core/Flask/blog/env/lib/python3.8/site-packages/flask/app.py", line 2447, in wsgi_app
    response = self.full_dispatch_request()
  File "/home/tom/moringa-core/Flask/blog/env/lib/python3.8/site-packages/flask/app.py", line 1952, in full_dispatch_request
    rv = self.handle_user_exception(e)
  File "/home/tom/moringa-core/Flask/blog/env/lib/python3.8/site-packages/flask/app.py", line 1821, in handle_user_exception
    reraise(exc_type, exc_value, tb)
  File "/home/tom/moringa-core/Flask/blog/env/lib/python3.8/site-packages/flask/_compat.py", line 39, in reraise
    raise value
  File "/home/tom/moringa-core/Flask/blog/env/lib/python3.8/site-packages/flask/app.py", line 1948, in full_dispatch_request
    rv = self.preprocess_request()
  File "/home/tom/moringa-core/Flask/blog/env/lib/python3.8/site-packages/flask/app.py", line 2242, in preprocess_request
    rv = func()
  File "/home/tom/moringa-core/Flask/blog/app/main/routes.py", line 16, in before_request
    g.locale = str(getocale())
NameError: name 'getocale' is not defined
2021-03-09 13:47:16,443 INFO: Microblog startup [in /home/tom/moringa-core/Flask/blog/app/__init__.py:68]
2021-03-09 13:47:19,218 ERROR: Exception on / [GET] [in /home/tom/moringa-core/Flask/blog/env/lib/python3.8/site-packages/flask/app.py:1891]
Traceback (most recent call last):
  File "/home/tom/moringa-core/Flask/blog/env/lib/python3.8/site-packages/flask/app.py", line 2447, in wsgi_app
    response = self.full_dispatch_request()
  File "/home/tom/moringa-core/Flask/blog/env/lib/python3.8/site-packages/flask/app.py", line 1952, in full_dispatch_request
    rv = self.handle_user_exception(e)
  File "/home/tom/moringa-core/Flask/blog/env/lib/python3.8/site-packages/flask/app.py", line 1821, in handle_user_exception
    reraise(exc_type, exc_value, tb)
  File "/home/tom/moringa-core/Flask/blog/env/lib/python3.8/site-packages/flask/_compat.py", line 39, in reraise
    raise value
  File "/home/tom/moringa-core/Flask/blog/env/lib/python3.8/site-packages/flask/app.py", line 1948, in full_dispatch_request
    rv = self.preprocess_request()
  File "/home/tom/moringa-core/Flask/blog/env/lib/python3.8/site-packages/flask/app.py", line 2242, in preprocess_request
    rv = func()
  File "/home/tom/moringa-core/Flask/blog/app/main/routes.py", line 16, in before_request
    g.locale = str(getocale())
NameError: name 'getocale' is not defined
2021-03-09 13:47:19,903 ERROR: Exception on /static/css/main.css [GET] [in /home/tom/moringa-core/Flask/blog/env/lib/python3.8/site-packages/flask/app.py:1891]
Traceback (most recent call last):
  File "/home/tom/moringa-core/Flask/blog/env/lib/python3.8/site-packages/flask/app.py", line 2447, in wsgi_app
    response = self.full_dispatch_request()
  File "/home/tom/moringa-core/Flask/blog/env/lib/python3.8/site-packages/flask/app.py", line 1952, in full_dispatch_request
    rv = self.handle_user_exception(e)
  File "/home/tom/moringa-core/Flask/blog/env/lib/python3.8/site-packages/flask/app.py", line 1821, in handle_user_exception
    reraise(exc_type, exc_value, tb)
  File "/home/tom/moringa-core/Flask/blog/env/lib/python3.8/site-packages/flask/_compat.py", line 39, in reraise
    raise value
  File "/home/tom/moringa-core/Flask/blog/env/lib/python3.8/site-packages/flask/app.py", line 1948, in full_dispatch_request
    rv = self.preprocess_request()
  File "/home/tom/moringa-core/Flask/blog/env/lib/python3.8/site-packages/flask/app.py", line 2242, in preprocess_request
    rv = func()
  File "/home/tom/moringa-core/Flask/blog/app/main/routes.py", line 16, in before_request
    g.locale = str(getocale())
NameError: name 'getocale' is not defined
2021-03-09 13:47:20,085 ERROR: Exception on /static/img/logo.png [GET] [in /home/tom/moringa-core/Flask/blog/env/lib/python3.8/site-packages/flask/app.py:1891]
Traceback (most recent call last):
  File "/home/tom/moringa-core/Flask/blog/env/lib/python3.8/site-packages/flask/app.py", line 2447, in wsgi_app
    response = self.full_dispatch_request()
  File "/home/tom/moringa-core/Flask/blog/env/lib/python3.8/site-packages/flask/app.py", line 1952, in full_dispatch_request
    rv = self.handle_user_exception(e)
  File "/home/tom/moringa-core/Flask/blog/env/lib/python3.8/site-packages/flask/app.py", line 1821, in handle_user_exception
    reraise(exc_type, exc_value, tb)
  File "/home/tom/moringa-core/Flask/blog/env/lib/python3.8/site-packages/flask/_compat.py", line 39, in reraise
    raise value
  File "/home/tom/moringa-core/Flask/blog/env/lib/python3.8/site-packages/flask/app.py", line 1948, in full_dispatch_request
    rv = self.preprocess_request()
  File "/home/tom/moringa-core/Flask/blog/env/lib/python3.8/site-packages/flask/app.py", line 2242, in preprocess_request
    rv = func()
  File "/home/tom/moringa-core/Flask/blog/app/main/routes.py", line 16, in before_request
    g.locale = str(getocale())
NameError: name 'getocale' is not defined
